Workbook

Sheet Frontpage
B1: DO NOT EDIT THIS TEMPLATE - CREATE A LOCAL COPY TO UPDATE!
B3: Welcome! | AH3: 2025
B4: This is the IT Cost estimation template. | AH4: 2026
B5: Please first select the investment year in cell A19 (the first year of the project) | AH5: 2027
B6: Please fill out each sheet in the bottom starting from the right at #1. | AH6: 2028
B7: Once all sheets from 1-5 are filled out, #6 will automatically be generated and give you/the Product Manager the right input to paste into the CAPEXInsights funding tool. | AH7: 2029
B8: Please read the guidelines to understand which fields to edit and which to leave (as some contains fixed formulars that will provide necessary calculations). | AH8: 2030
B10: Ensure to fill out below who has signed off on the template
B11: Signed off by | C11: Date:
B12: Name.. | C12: DD-MM-YYYY
B14: Table of content | D14: Guidelines to each sheet
B15: Resource Estimates
B16: Resource Cost Assumptions
B17: IT Services (OPS) cost
B18: Other costs
B19: Cost Overview
B20: CAPEXInsights
B22: Please select investment year:
B23: 2026

Sheet #1 Resource Estimates
A1: DO NOT EDIT THIS TEMPLATE - CREATE A LOCAL COPY TO UPDATE!
A3: Work Estimation Details | E3: Optimistic | F3: Most Likely | G3: Pessimistic | H3: Confidence
A4: Delivery headline | B4: In scope assumptions | C4: Out of scope assumptions | D4: Cost Type | E4: Effort Hrs | F4: Effort Hrs | G4: Effort Hrs | H4: Factor | I4: Confidence | J4: Weighted average | K4: Confidence | L4: Confidence | M4: Comments
A5: Set up architectural landscape | D5: IT | E5: 10 | F5: 40 | G5: 100 | H5: =(G5-E5)/6 -> 15 | I5: =(E5+G5+(4*F5))/6 -> 45 | J5: =IF(H5+I5=0,"",H5+I5) -> 60 | K5: =I5+(2*H5) -> 75
A6: Development of xyZ | D6: IT | H6: =(G6-E6)/6 -> 0 | I6: =(E6+G6+(4*F6))/6 -> 0 | J6: =IF(H6+I6=0,"",H6+I6) | K6: =I6+(2*H6) -> 0
A7: xyz | D7: IT | H7: =(G7-E7)/6 -> 0 | I7: =(E7+G7+(4*F7))/6 -> 0 | J7: =IF(H7+I7=0,"",H7+I7) | K7: =I7+(2*H7) -> 0
D8: IT | H8: =(G8-E8)/6 -> 0 | I8: =(E8+G8+(4*F8))/6 -> 0 | J8: =IF(H8+I8=0,"",H8+I8) | K8: =I8+(2*H8) -> 0
A9: Area 2 | D9: IT | H9: =(G9-E9)/6 -> 0 | I9: =(E9+G9+(4*F9))/6 -> 0 | J9: =IF(H9+I9=0,"",H9+I9) | K9: =I9+(2*H9) -> 0
A10: Sub area/task | D10: IT | H10: =(G10-E10)/6 -> 0 | I10: =(E10+G10+(4*F10))/6 -> 0 | J10: =IF(H10+I10=0,"",H10+I10) | K10: =I10+(2*H10) -> 0
D11: IT | H11: =(G11-E11)/6 -> 0 | I11: =(E11+G11+(4*F11))/6 -> 0 | J11: =IF(H11+I11=0,"",H11+I11) | K11: =I11+(2*H11) -> 0
D12: IT | H12: =(G12-E12)/6 -> 0 | I12: =(E12+G12+(4*F12))/6 -> 0 | J12: =IF(H12+I12=0,"",H12+I12) | K12: =I12+(2*H12) -> 0
A13: Area 3 | D13: IT | H13: =(G13-E13)/6 -> 0 | I13: =(E13+G13+(4*F13))/6 -> 0 | J13: =IF(H13+I13=0,"",H13+I13) | K13: =I13+(2*H13) -> 0
A14: Sub area/task | D14: IT | H14: =(G14-E14)/6 -> 0 | I14: =(E14+G14+(4*F14))/6 -> 0 | J14: =IF(H14+I14=0,"",H14+I14) | K14: =I14+(2*H14) -> 0
D15: IT | H15: =(G15-E15)/6 -> 0 | I15: =(E15+G15+(4*F15))/6 -> 0 | J15: =IF(H15+I15=0,"",H15+I15) | K15: =I15+(2*H15) -> 0
D16: IT | H16: =(G16-E16)/6 -> 0 | I16: =(E16+G16+(4*F16))/6 -> 0 | J16: =IF(H16+I16=0,"",H16+I16) | K16: =I16+(2*H16) -> 0
D17: IT | H17: =(G17-E17)/6 -> 0 | I17: =(E17+G17+(4*F17))/6 -> 0 | J17: =IF(H17+I17=0,"",H17+I17) | K17: =I17+(2*H17) -> 0
A18: Area 4 | D18: IT | H18: =(G18-E18)/6 -> 0 | I18: =(E18+G18+(4*F18))/6 -> 0 | J18: =IF(H18+I18=0,"",H18+I18) | K18: =I18+(2*H18) -> 0
A19: Sub area/task | D19: IT | H19: =(G19-E19)/6 -> 0 | I19: =(E19+G19+(4*F19))/6 -> 0 | J19: =IF(H19+I19=0,"",H19+I19) | K19: =I19+(2*H19) -> 0
D20: IT | H20: =(G20-E20)/6 -> 0 | I20: =(E20+G20+(4*F20))/6 -> 0 | J20: =IF(H20+I20=0,"",H20+I20) | K20: =I20+(2*H20) -> 0
D21: IT | H21: =(G21-E21)/6 -> 0 | I21: =(E21+G21+(4*F21))/6 -> 0 | J21: =IF(H21+I21=0,"",H21+I21) | K21: =I21+(2*H21) -> 0
D22: IT | H22: =(G22-E22)/6 -> 0 | I22: =(E22+G22+(4*F22))/6 -> 0 | J22: =IF(H22+I22=0,"",H22+I22) | K22: =I22+(2*H22) -> 0
A23: Area 4 | D23: IT | H23: =(G23-E23)/6 -> 0 | I23: =(E23+G23+(4*F23))/6 -> 0 | J23: =IF(H23+I23=0,"",H23+I23) | K23: =I23+(2*H23) -> 0
A24: Sub area/task | D24: IT | H24: =(G24-E24)/6 -> 0 | I24: =(E24+G24+(4*F24))/6 -> 0 | J24: =IF(H24+I24=0,"",H24+I24) | K24: =I24+(2*H24) -> 0
D25: IT | H25: =(G25-E25)/6 -> 0 | I25: =(E25+G25+(4*F25))/6 -> 0 | J25: =IF(H25+I25=0,"",H25+I25) | K25: =I25+(2*H25) -> 0
A26: Area 4 | D26: IT | H26: =(G26-E26)/6 -> 0 | I26: =(E26+G26+(4*F26))/6 -> 0 | J26: =IF(H26+I26=0,"",H26+I26) | K26: =I26+(2*H26) -> 0
A27: Sub area/task | D27: IT | H27: =(G27-E27)/6 -> 0 | I27: =(E27+G27+(4*F27))/6 -> 0 | J27: =IF(H27+I27=0,"",H27+I27) | K27: =I27+(2*H27) -> 0
D28: IT | H28: =(G28-E28)/6 -> 0 | I28: =(E28+G28+(4*F28))/6 -> 0 | J28: =IF(H28+I28=0,"",H28+I28) | K28: =I28+(2*H28) -> 0
D29: IT | H29: =(G29-E29)/6 -> 0 | I29: =(E29+G29+(4*F29))/6 -> 0 | J29: =IF(H29+I29=0,"",H29+I29) | K29: =I29+(2*H29) -> 0
A30: SUM | E30: =SUM(E5:E29) -> 10 | F30: =SUM(F5:F29) -> 40 | G30: =SUM(G5:G29) -> 100
A32: Test Management | D32: IT | H32: =(G32-E32)/6 -> 0 | I32: =(E32+G32+(4*F32))/6 -> 0 | J32: =IF(H32+I32=0,"",H32+I32) | K32: =I32+(2*H32) -> 0
D33: =IF(C33=0,"","IT") | H33: =(G33-E33)/6 -> 0 | I33: =(E33+G33+(4*F33))/6 -> 0 | J33: =IF(H33+I33=0,"",H33+I33) | K33: =I33+(2*H33) -> 0
A34: Cutover | D34: IT | H34: =(G34-E34)/6 -> 0 | I34: =(E34+G34+(4*F34))/6 -> 0 | J34: =IF(H34+I34=0,"",H34+I34) | K34: =I34+(2*H34) -> 0
H35: =(G35-E35)/6 -> 0 | I35: =(E35+G35+(4*F35))/6 -> 0 | J35: =IF(H35+I35=0,"",H35+I35) | K35: =I35+(2*H35) -> 0
A36: Hypercare | D36: IT | H36: =(G36-E36)/6 -> 0 | I36: =(E36+G36+(4*F36))/6 -> 0 | J36: =IF(H36+I36=0,"",H36+I36) | K36: =I36+(2*H36) -> 0
H37: =(G37-E37)/6 -> 0 | I37: =(E37+G37+(4*F37))/6 -> 0 | J37: =IF(H37+I37=0,"",H37+I37) | K37: =I37+(2*H37) -> 0
A38: BCM | D38: IT | E38: 0 | F38: 0 | G38: 0 | H38: =(G38-E38)/6 -> 0 | I38: =(E38+G38+(4*F38))/6 -> 0 | J38: =IF(H38+I38=0,"",H38+I38) | K38: =I38+(2*H38) -> 0
H39: =(G39-E39)/6 -> 0 | I39: =(E39+G39+(4*F39))/6 -> 0 | J39: =IF(H39+I39=0,"",H39+I39) | K39: =I39+(2*H39) -> 0
A40: User Experience | D40: IT | H40: =(G40-E40)/6 -> 0 | I40: =(E40+G40+(4*F40))/6 -> 0 | J40: =IF(H40+I40=0,"",H40+I40) | K40: =I40+(2*H40) -> 0
H41: =(G41-E41)/6 -> 0 | I41: =(E41+G41+(4*F41))/6 -> 0 | J41: =IF(H41+I41=0,"",H41+I41) | K41: =I41+(2*H41) -> 0
A42: Data quality improvement | D42: IT | H42: =(G42-E42)/6 -> 0 | I42: =(E42+G42+(4*F42))/6 -> 0 | J42: =IF(H42+I42=0,"",H42+I42) | K42: =I42+(2*H42) -> 0
...

Sheet #2 Resource Cost Assumptions
A1: DO NOT EDIT THIS TEMPLATE - CREATE A LOCAL COPY TO UPDATE!
A3: Resource cost assumptions
A5: Internal Resources DK,GE,UK,SE/PL resource split | B5: Value | C5: Describe the location split of the internal IT resources and the rationale behind the split
A6: DK, GE, UK & SE resource fraction | B6: 0.3 | C6: …...Put description here
A7: PL resource fraction (Computed - do NOT change) | B7: =1-B6 -> 0.7
A9: IT Resources Internal / external resource split | B9: Value | C9: Describe the split between internal and external IT resources and the rationale behind the split
A10: Internal IT resource fraction | B10: 1 | C10: …...Put description here
A11: External IT 1 resource fraction | B11: 0
A12: External IT 2 resource fraction | B12: 0
A13: External IT 3 resource fraction | B13: 0
A14: Total | B14: =SUM(B10:B13) -> 1 | C14: =IF(B14=1,"OK","Not OK") -> OK
A16: Internal & External avg. cost assumptions | B16: Average hourly cost (€) | C16: Describe rationale behind avg. hourly cost
A17: Internal IT (DK, GE, UK, SE) | B17: 92 | C17: Average rate level 5-10 employees
A18: Internal IT (PL) | B18: 61 | C18: Average rate level 5-10 employees
A19: External IT 1 | B19: 135
A20: External IT 2 | B20: 91
A21: External IT 3 | B21: 78
A23: Blended Rate | B23: =(B10*B6*B17+B10*B7*B18)+(B11*B19+B12*B20+B13*B21) -> 70.3

Sheet #3 IT Services (OPS) cost
A1: DO NOT EDIT THIS TEMPLATE - CREATE A LOCAL COPY TO UPDATE!
AO2: DO NOT DELETE
B3: Step 1.0 (Mandatory) | C3: Will project affect IT Operational Cost? | E3: Yes | F3: =IF(E3="Yes","Fill in Step 2 and Step 3.0",IF(E3="No","Only fill in Step 2","")) -> Fill in Step 2 and Step 3.0 | AO3: Drop Down
B4: Step 1.1 (Mandatory) | C4: Will the project lead to sunsetting an existing IT Solution? | E4: Yes | F4: =IF(E4="Yes","Fill in Step 3.1",IF(E4="No","Leave step 3.1 empty","")) -> Fill in Step 3.1
AO5: Yes
B6: Step 2 (Mandatory) | C6: Contacts in IT Services - Who have been involved in cost estimations (see contact list) | AO6: No
C7: Application Services | D7: xxx
C8: Infrastructure Services | D8: yyy
C9: Other | D9: zzz
B11: Step 3.0 | C11: Additional Operations Cost | G11: Amounts to be inserted as a positive number tEUR (eg. 20) | M11: Instructions
C12: Category | D12: Type | E12: Description | F12: Vendor (if known) | G12: =Frontpage!$B$23 -> 2026 | H12: =Frontpage!$B$23+1 -> 2027 | I12: =H12+1 -> 2028 | J12: =I12+1 -> 2029 | K12: =J12+1 -> 2030
G13: (first year - project cost)
C14: Application cost | D14: License cost/Saas/Subscription | E14: System/tool information | M14: - The table is a gross list of potential cost, fill in relevant lines (add new if needed)
C15: Application cost | D15: Support/Enhancements/Maintenance | E15: Consultants to support the solution | M15: - Remember to include expected cost increases beyond year 1
C16: Internal headcount | D16: Internal headcount (do we need additional resources for support?) | E16: Internal (please indicate number of FTEs) | M16: - In case of acquisition cases, please use the 'FTE driven cost template'
C17: Azure | D17: Azure | E17: Servers/storage and other services from Azure
C18: Infrastructure/DC | D18: Server/Storage | E18: Servers/storage etc. at Aeven
C19: Infrastructure/DC | D19: Network | E19: LAN, WAN and Firewall
C20: Devices | D20: Devices | E20: Device type
C21: Other | D21: Other Services
C22: Total operational cost | G22: =ROUND(SUM(G14:G21),1) -> 0 | H22: =ROUND(SUM(H14:H21),1) -> 0 | I22: =ROUND(SUM(I14:I21),1) -> 0 | J22: =ROUND(SUM(J14:J21),1) -> 0 | K22: =ROUND(SUM(K14:K21),1) -> 0
B24: Step 3.1 | C24: Sunsetting existing applications (Only relevant if sunsetting existing applications/systems) | G24: Amounts to be inserted with a negative number tEUR (eg. -20)
C25: Category | D25: Type | E25: Description | F25: Vendor (if known) | G25: =Frontpage!$B$23 -> 2026 | H25: =H12 -> 2027 | I25: =I12 -> 2028 | J25: =J12 -> 2029 | K25: =K12 -> 2030
C26: Application cost | D26: License cost/Saas/Subscription | E26: System/tool information
C27: Infrastructure/DC | D27: Server/Storage
C28: Other | D28: Other Services
C29: Total cost reduction from sunsetting existing systems | G29: =ROUND(SUM(G26:G28),1) -> 0 | H29: =ROUND(SUM(H26:H28),1) -> 0 | I29: =ROUND(SUM(I26:I28),1) -> 0 | J29: =ROUND(SUM(J26:J28),1) -> 0 | K29: =ROUND(SUM(K26:K28),1) -> 0
C31: Project cost | G31: =G22 -> 0
C32: IT Services (OPS) cost | G32: =G29 -> 0 | H32: =+H22+H29 -> 0 | I32: =+I22+I29 -> 0 | J32: =+J22+J29 -> 0 | K32: =+K22+K29 -> 0
B34: Contact list | C34: Contact list
C35: Technology and Functional areas | D35: Service Owners | E35: Department
C36: Data Foundation Support | D36: Agnieszka Swistak | E36: Application Services - Intelligent Automation and Data Lake
C37: Robotics support | D37: Agnieszka Swistak | E37: Application Services - Intelligent Automation and Data Lake
C38: PowerApps, powerplatform, Sharepoint | D38: Agnieszka Swistak | E38: Application Services - Intelligent Automation and Data Lake
C39: Supply Chain & Planning | D39: Morten Korgaard Johansson | E39: Application Services - Supply Chain Planning
C40: Commercial Applications | D40: Dorte Brit Lau Malling | E40: Application Services - Commercial & Technology
C41: EDI & Integrations | D41: Dorte Brit Lau Malling | E41: Application Services - Commercial & Technology
C42: Marketing & Innovation Aplications | D42: Lene Dalby | E42: Application Services - MI & ASC
C43: Agriculture, Sustainability & Communicatin | D43: Lene Dalby | E43: Application Services - MI & ASC
C44: HR applications | D44: Agnieszka Widlak | E44: Application Services - HR, Finance @ MDO support
...

Sheet #6 CAPEXInsights
A1: DO NOT EDIT THIS TEMPLATE - CREATE A LOCAL COPY TO UPDATE!
A3: Please insert the numbers in CAPEXInsights as EUR and with the same sign (positive or negative) as shown below
A5: To be inserted in the Budget Development tab
A7: Total business case cost (EUR) | C7: Total | D7: =Frontpage!$B$23 -> 2026 | E7: =D7+1 -> 2027 | F7: =E7+1 -> 2028 | G7: =F7+1 -> 2029 | H7: =G7+1 -> 2030
B8: CAPEX | C8: =IF(SUM(D8:H8)=0,"",SUM(D8:H8)) | D8: =IF(('#5 Cost Overview'!D14+'#5 Cost Overview'!D26)*(1-'#5 Cost Overview'!$B$8)*1000=0,"",('#5 Cost Overview'!D14+'#5 Cost Overview'!D26)*(1-'#5 Cost Overview'!$B$8)*1000) | E8: =IF(('#5 Cost Overview'!E14+'#5 Cost Overview'!E26)*(1-'#5 Cost Overview'!$B$8)*1000=0,"",('#5 Cost Overview'!E14+'#5 Cost Overview'!E26)*(1-'#5 Cost Overview'!$B$8)*1000) | F8: =IF(('#5 Cost Overview'!F14+'#5 Cost Overview'!F26)*(1-'#5 Cost Overview'!$B$8)*1000=0,"",('#5 Cost Overview'!F14+'#5 Cost Overview'!F26)*(1-'#5 Cost Overview'!$B$8)*1000) | G8: =IF(('#5 Cost Overview'!G14+'#5 Cost Overview'!G26)*(1-'#5 Cost Overview'!$B$8)*1000=0,"",('#5 Cost Overview'!G14+'#5 Cost Overview'!G26)*(1-'#5 Cost Overview'!$B$8)*1000) | H8: =IF(('#5 Cost Overview'!H14+'#5 Cost Overview'!H26)*(1-'#5 Cost Overview'!$B$8)*1000=0,"",('#5 Cost Overview'!H14+'#5 Cost Overview'!H26)*(1-'#5 Cost Overview'!$B$8)*1000)
B9: Contingency | C9: =IF(SUM(D9:H9)=0,"",SUM(D9:H9)) | D9: =IF('#5 Cost Overview'!D18*1000=0,"",'#5 Cost Overview'!D18*1000) | E9: =IF('#5 Cost Overview'!E18*1000=0,"",'#5 Cost Overview'!E18*1000) | F9: =IF('#5 Cost Overview'!F18*1000=0,"",'#5 Cost Overview'!F18*1000) | G9: =IF('#5 Cost Overview'!G18*1000=0,"",'#5 Cost Overview'!G18*1000) | H9: =IF('#5 Cost Overview'!H18*1000=0,"",'#5 Cost Overview'!H18*1000)
B10: IT project OPEX costs | C10: =IF(SUM(D10:H10)=0,"",SUM(D10:H10)) -> 30004800 | D10: =IF(('#5 Cost Overview'!D14+'#5 Cost Overview'!D26)*('#5 Cost Overview'!$B$8)*1000=0,"",('#5 Cost Overview'!D14+'#5 Cost Overview'!D26)*('#5 Cost Overview'!$B$8)*1000) -> 30004600 | E10: =IF(('#5 Cost Overview'!E14+'#5 Cost Overview'!E26)*('#5 Cost Overview'!$B$8)*1000=0,"",('#5 Cost Overview'!E14+'#5 Cost Overview'!E26)*('#5 Cost Overview'!$B$8)*1000) -> 200 | F10: =IF(('#5 Cost Overview'!F14+'#5 Cost Overview'!F26)*('#5 Cost Overview'!$B$8)*1000=0,"",('#5 Cost Overview'!F14+'#5 Cost Overview'!F26)*('#5 Cost Overview'!$B$8)*1000) | G10: =IF(('#5 Cost Overview'!G14+'#5 Cost Overview'!G26)*('#5 Cost Overview'!$B$8)*1000=0,"",('#5 Cost Overview'!G14+'#5 Cost Overview'!G26)*('#5 Cost Overview'!$B$8)*1000) | H10: =IF(('#5 Cost Overview'!H14+'#5 Cost Overview'!H26)*('#5 Cost Overview'!$B$8)*1000=0,"",('#5 Cost Overview'!H14+'#5 Cost Overview'!H26)*('#5 Cost Overview'!$B$8)*1000)
A13: To be inserted in the Business Case Calculator tab
A15: Total business case cost (EUR) | D15: =Frontpage!$B$23 -> 2026 | E15: =D15+1 -> 2027 | F15: =E15+1 -> 2028 | G15: =F15+1 -> 2029 | H15: =G15+1 -> 2030
A16: Field: Change in Volume and Profit & Loss | B16: IT project OPEX costs | D16: =IF(-('#5 Cost Overview'!D14+'#5 Cost Overview'!D26)*('#5 Cost Overview'!$B$8)*1000=0,"",-('#5 Cost Overview'!D14+'#5 Cost Overview'!D26)*('#5 Cost Overview'!$B$8)*1000) -> -30004600 | E16: =IF(-('#5 Cost Overview'!E14+'#5 Cost Overview'!E26)*('#5 Cost Overview'!$B$8)*1000=0,"",-('#5 Cost Overview'!E14+'#5 Cost Overview'!E26)*('#5 Cost Overview'!$B$8)*1000) -> -200 | F16: =IF(-('#5 Cost Overview'!F14+'#5 Cost Overview'!F26)*('#5 Cost Overview'!$B$8)*1000=0,"",-('#5 Cost Overview'!F14+'#5 Cost Overview'!F26)*('#5 Cost Overview'!$B$8)*1000) | G16: =IF(-('#5 Cost Overview'!G14+'#5 Cost Overview'!G26)*('#5 Cost Overview'!$B$8)*1000=0,"",-('#5 Cost Overview'!G14+'#5 Cost Overview'!G26)*('#5 Cost Overview'!$B$8)*1000) | H16: =IF(-('#5 Cost Overview'!H14+'#5 Cost Overview'!H26)*('#5 Cost Overview'!$B$8)*1000=0,"",-('#5 Cost Overview'!H14+'#5 Cost Overview'!H26)*('#5 Cost Overview'!$B$8)*1000)
A17: Field: Change in Volume and Profit & Loss | B17: IT Operations: Change in operational costs | D17: =IF(-'#5 Cost Overview'!D30*1000=0,"",-'#5 Cost Overview'!D30*1000) | E17: =IF(-'#5 Cost Overview'!E30*1000=0,"",-'#5 Cost Overview'!E30*1000) | F17: =IF(-'#5 Cost Overview'!F30*1000=0,"",-'#5 Cost Overview'!F30*1000) | G17: =IF(-'#5 Cost Overview'!G30*1000=0,"",-'#5 Cost Overview'!G30*1000) | H17: =IF(-'#5 Cost Overview'!H30*1000=0,"",-'#5 Cost Overview'!H30*1000)
A18: Field: CAPEX Amount Requested | B18: Intangible assets (incl. IT project CAPEX costs) | D18: =IF(('#5 Cost Overview'!D14+'#5 Cost Overview'!D26)*(1-'#5 Cost Overview'!$B$8)*1000=0,"",('#5 Cost Overview'!D14+'#5 Cost Overview'!D26)*(1-'#5 Cost Overview'!$B$8)*1000) | E18: =IF(('#5 Cost Overview'!E14+'#5 Cost Overview'!E26)*(1-'#5 Cost Overview'!$B$8)*1000=0,"",('#5 Cost Overview'!E14+'#5 Cost Overview'!E26)*(1-'#5 Cost Overview'!$B$8)*1000) | F18: =IF(('#5 Cost Overview'!F14+'#5 Cost Overview'!F26)*(1-'#5 Cost Overview'!$B$8)*1000=0,"",('#5 Cost Overview'!F14+'#5 Cost Overview'!F26)*(1-'#5 Cost Overview'!$B$8)*1000) | G18: =IF(('#5 Cost Overview'!G14+'#5 Cost Overview'!G26)*(1-'#5 Cost Overview'!$B$8)*1000=0,"",('#5 Cost Overview'!G14+'#5 Cost Overview'!G26)*(1-'#5 Cost Overview'!$B$8)*1000) | H18: =IF(('#5 Cost Overview'!H14+'#5 Cost Overview'!H26)*(1-'#5 Cost Overview'!$B$8)*1000=0,"",('#5 Cost Overview'!H14+'#5 Cost Overview'!H26)*(1-'#5 Cost Overview'!$B$8)*1000)
A19: Field: CAPEX Amount Requested | B19: Contingency | D19: =IF('#5 Cost Overview'!D18*1000=0,"",'#5 Cost Overview'!D18*1000) | E19: =IF('#5 Cost Overview'!E18*1000=0,"",'#5 Cost Overview'!E18*1000) | F19: =IF('#5 Cost Overview'!F18*1000=0,"",'#5 Cost Overview'!F18*1000) | G19: =IF('#5 Cost Overview'!G18*1000=0,"",'#5 Cost Overview'!G18*1000) | H19: =IF('#5 Cost Overview'!H18*1000=0,"",'#5 Cost Overview'!H18*1000)

Sheet #4 Other Costs
A1: DO NOT EDIT THIS TEMPLATE - CREATE A LOCAL COPY TO UPDATE!
A3: Item | B3: Description | C3: tEUR | AM3: Travel
A4: Travel | B4: … | AM4: Hardware
A5: Hardware | C5: 30000 | AM5: Fix price vendor deliverables
A6: Fix price vendor deliverables | AM6: Other
A7: Other
A26: Grand total -Other Costs | C26: =SUM(C4:C25) -> 30000

Sheet #5 Cost Overview
A1: DO NOT EDIT THIS TEMPLATE - CREATE A LOCAL COPY TO UPDATE!
C2: Total inv. (tEUR) | D2: =Frontpage!$B$23 -> 2026 | E2: =D2+1 -> 2027 | F2: =E2+1 -> 2028 | G2: =F2+1 -> 2029 | H2: =G2+1 -> 2030
A3: Project cost | C3: =C14+C18+C26 -> 30004.8 | D3: =D14+D18+D26 -> 30004.6 | E3: =E14+E18+E26 -> 0.2 | F3: =F14+F18+F26 -> 0 | G3: =G14+G18+G26 -> 0 | H3: =H14+H18+H26 -> 0 | I3: =IF(SUM(D3:H3)=C3,"OK","Not OK") -> OK
A4: IT Services (OPS) cost | C4: =SUM(D4:H4) -> 0 | D4: =D30 -> 0 | E4: =E30 -> 0 | F4: =F30 -> 0 | G4: =G30 -> 0 | H4: =H30 -> 0
A5: Total business case cost | C5: =SUM(C3:C4) -> 30004.8 | D5: =SUM(D3:D4) -> 30004.6 | E5: =SUM(E3:E4) -> 0.2 | F5: =SUM(F3:F4) -> 0 | G5: =SUM(G3:G4) -> 0 | H5: =SUM(H3:H4) -> 0
A8: OPEX SHARE | B8: 1 | C8: =IF(C14=0,"",IF(AND(B8<>1,C14*(1-$B$8)<10)," ← The project is too small to be capitalized - please change the OPEX SHARE in cell B8 to 100%",""))
A10: Resource cost estimate (based on 85% confidence in resource estimates) | B10: Hours | C10: Cost (tEUR) | D10: =Frontpage!$B$23 -> 2026 | E10: =D10+1 -> 2027 | F10: =E10+1 -> 2028 | G10: =F10+1 -> 2029 | H10: =G10+1 -> 2030 | I10: Check | J10: Still to be distributed | M10: Yes | N10: Calculated contingency
A11: Internal IT | B11: =('#1 Resource Estimates'!B51*'#2 Resource Cost Assumptions'!B10) -> 45.2 | C11: =ROUND(((B11*'#2 Resource Cost Assumptions'!B17*'#2 Resource Cost Assumptions'!B6)+(B11*'#2 Resource Cost Assumptions'!B18*'#2 Resource Cost Assumptions'!B7))/1000,1) -> 3.2 | D11: 3 | E11: 0.2 | I11: =IF(SUM(D11:H11)=C11,"OK","Not OK") -> OK | J11: =C11-SUM(D11:H11) -> 0 | M11: No | N11: Self-defined contingency
A12: External IT | B12: =('#1 Resource Estimates'!B51*SUM('#2 Resource Cost Assumptions'!B11:B13)) -> 0 | C12: =IFERROR(ROUND(((B12*'#2 Resource Cost Assumptions'!B19*('#2 Resource Cost Assumptions'!B11/SUM('#2 Resource Cost Assumptions'!$B$11:$B$13)))+(B12*'#2 Resource Cost Assumptions'!B20*('#2 Resource Cost Assumptions'!B12/SUM('#2 Resource Cost Assumptions'!$B$11:$B$13)))+(B12*'#2 Resource Cost Assumptions'!B21*('#2 Resource Cost Assumptions'!B13/SUM('#2 Resource Cost Assumptions'!$B$11:$B$13))))/1000,1),0) -> 0 | I12: =IF(SUM(D12:H12)=C12,"OK","Not OK") -> OK | J12: =C12-SUM(D12:H12) -> 0
A13: Contingency (IT hours - internal/external mix) | B13: ='#1 Resource Estimates'!B52 -> 22.6 | C13: =ROUND(((B13*'#2 Resource Cost Assumptions'!$B$23)/1000),1) -> 1.6 | D13: 1.6 | I13: =IF(SUM(D13:H13)=C13,"OK","Not OK") -> OK | J13: =C13-SUM(D13:H13) -> 0 | L13: Bigger than 500 tEUR: | O13: =IF($C$3>500,"Yes","No") -> Yes
A14: Resources - subtotal | B14: =SUM(B11:B13) -> 67.8 | C14: =ROUND(SUM(C11:C13),1) -> 4.8 | D14: =ROUND(SUM(D11:D13),1) -> 4.6 | E14: =ROUND(SUM(E11:E13),1) -> 0.2 | F14: =ROUND(SUM(F11:F13),1) -> 0 | G14: =ROUND(SUM(G11:G13),1) -> 0 | H14: =ROUND(SUM(H11:H13),1) -> 0 | I14: =IF(SUM(D14:H14)=C14,"OK","Not OK") -> OK | J14: =C14-SUM(D14:H14) -> 0
A16: Contingency | B16: Description | C16: Cost (tEUR) | D16: =Frontpage!$B$23 -> 2026 | E16: =D16+1 -> 2027 | F16: =E16+1 -> 2028 | G16: =F16+1 -> 2029 | H16: =G16+1 -> 2030
A17: Additional contingency (manually added on top IT hours contingency) | B17: Please desribe the reason behind additional contingency | I17: =IF(SUM(D17:H17)=C17,"OK","Not OK") -> OK | J17: =C17-SUM(D17:H17) -> 0 | L17: <-- If project cost is above 500 tEUR, then it is mandatory to evaluate whether 'Additional contingency' is needed (cell C17 will be colored green) Projects below 500 tEUR is also allowed to add 'Additional contingency', but it is not mandatory - please read below implications: This particular contingency is part of the approved funding (hence, what you get approved by e.g. CFO is OPEX+CAPEX+contingency). However, the target will only be OPEX+CAPEX, since we do not expect you to use the contingency. If the target is not sufficient and you need to use some of the contingency, then you need to create a change request in CAPEXInsights (this will not have to be presented to e.g., CFO once again but can be approved by the sponsor).
A18: Total contigency | C18: =ROUND(SUM(C17),1) -> 0 | D18: =ROUND(SUM(D17),1) -> 0 | E18: =ROUND(SUM(E17),1) -> 0 | F18: =ROUND(SUM(F17),1) -> 0 | G18: =ROUND(SUM(G17),1) -> 0 | H18: =ROUND(SUM(H17),1) -> 0 | I18: =IF(SUM(D18:H18)=C18,"OK","Not OK") -> OK | J18: =C18-SUM(D18:H18) -> 0
A20: Other costs | C20: Cost (tEUR) | D20: =Frontpage!$B$23 -> 2026 | E20: =D20+1 -> 2027 | F20: =E20+1 -> 2028 | G20: =F20+1 -> 2029 | H20: =G20+1 -> 2030 | I20: Check
A21: Travel | C21: =ROUND(SUMIF('#4 Other Costs'!$A$4:$A$25,$A21,'#4 Other Costs'!$C$4:$C$25),1) -> 0 | I21: =IF(SUM(D21:H21)=C21,"OK","Not OK") -> OK | J21: =C21-SUM(D21:H21) -> 0
A22: Hardware | C22: =ROUND(SUMIF('#4 Other Costs'!$A$4:$A$25,$A22,'#4 Other Costs'!$C$4:$C$25),1) -> 30000 | D22: 30000 | I22: =IF(SUM(D22:H22)=C22,"OK","Not OK") -> OK | J22: =C22-SUM(D22:H22) -> 0
A23: Fix price vendor deliverables | C23: =ROUND(SUMIF('#4 Other Costs'!$A$4:$A$25,$A23,'#4 Other Costs'!$C$4:$C$25),1) -> 0 | I23: =IF(SUM(D23:H23)=C23,"OK","Not OK") -> OK | J23: =C23-SUM(D23:H23) -> 0
A24: Other | C24: =ROUND(SUMIF('#4 Other Costs'!$A$4:$A$25,$A24,'#4 Other Costs'!$C$4:$C$25),1) -> 0 | I24: =IF(SUM(D24:H24)=C24,"OK","Not OK") -> OK | J24: =C24-SUM(D24:H24) -> 0
A25: Licenses etc. (first year) - from the '#3 IT Services (OPS) cost' tab | C25: ='#3 IT Services (OPS) cost'!G31 -> 0 | D25: =C25 -> 0 | I25: =IF(SUM(D25:H25)=C25,"OK","Not OK") -> OK | J25: =C25-SUM(D25:H25) -> 0
A26: Other costs - subtotal | C26: =ROUND(SUM(C21:C25),1) -> 30000 | D26: =ROUND(SUM(D21:D25),1) -> 30000 | E26: =ROUND(SUM(E21:E25),1) -> 0 | F26: =ROUND(SUM(F21:F25),1) -> 0 | G26: =ROUND(SUM(G21:G25),1) -> 0 | H26: =ROUND(SUM(H21:H25),1) -> 0 | I26: =IF(SUM(D26:H26)=C26,"OK","Not OK") -> OK | J26: =C26-SUM(D26:H26) -> 0
A29: IT Services (OPS) cost | D29: =Frontpage!$B$23 -> 2026 | E29: =D29+1 -> 2027 | F29: =E29+1 -> 2028 | G29: =F29+1 -> 2029 | H29: =G29+1 -> 2030
A30: IT Services (OPS) cost | D30: ='#3 IT Services (OPS) cost'!G32 -> 0 | E30: ='#3 IT Services (OPS) cost'!H32 -> 0 | F30: ='#3 IT Services (OPS) cost'!I32 -> 0 | G30: ='#3 IT Services (OPS) cost'!J32 -> 0 | H30: ='#3 IT Services (OPS) cost'!K32 -> 0

Sheet Optional! SAP&FTE driven cost 
B2: RELEVANT IF NEW EMPLOYEES ARE HIRED AS PART OF THE PROJECT OR IF THE PROJECT IS AFFECTING SAP LICENSES (Licenses for SAP and Microsoft 365 (only basic licenses))
B3: Please always reach out to vendor management (Henrik Albinus) if utilizing this template
B6: EUR
B7: Input* | C7: Metric | D7: Blocks of | E7: Number
B8: Number of employees/headcounts | C8: User/Headcounts (SuccessFactors/M365 F5) | D8: 1
B9: - hereoff number with an Arla laptop | C9: User/Headcounts (SuccessFactors/M365 E5) | D9: 1
B10: Number of FTE (for SAP on-prem) | C10: FTE (S/4HANA on-prem single metric) | D10: 1
B11: Concur - number of claims | C11: No of claim/year | D11: 1
B12: DocuSign - number of envelopes | C12: No of envelopes/year | D12: 1
B13: SAP IBP (all 5 modules) | C13: Revenue per year | D13: 500.000.000 EUR
B14: SAP TM | C14: Freight spend year | D14: 2.500.000 EUR
B15: SAP EWM | C15: Delivery items per day | D15: 5000
B16: Total one-time | E16: =E34+E46+E49 -> 0
B17: Total annual cost | E17: =E23+E28+F34+E37+E40+E43+F46+F49 -> 0
B19: SuccessFactor | C19: Metric | D19: Annual price | E19: Total/year
B20: Employee central | C20: User/Headcounts (SuccessFactors/M365 F5) | D20: 13.8 | E20: =$D$35*D20 -> 0
B21: Talent Management | C21: User/Headcounts (SuccessFactors/M365 F5) | D21: 31.94 | E21: =$D$35*D21 -> 0
B22: Onboarding | C22: User/Headcounts (SuccessFactors/M365 F5) | D22: 4.48 | E22: =$D$35*D22 -> 0
B23: Total | E23: =SUM(E20:E22) -> 0
B25: Microsoft M365 | C25: Metric | D25: Annual price | E25: Total/year
B26: Microsoft Office F5 | C26: User/Headcounts (SuccessFactors/M365 F5) | D26: =12*9.86 -> 118.32 | E26: =(E8-E9)*D26 -> 0
B27: Microsoft Office incl OS E5 | C27: User/Headcounts (SuccessFactors/M365 E5) | D27: =12*36.03 -> 432.36 | E27: =E9*D27 -> 0
B28: Total | E28: =SUM(E26:E27) -> 0
B31: SAP PS1 (on-prem) | C31: Metric | D31: One time/FTE | E31: Total one time | F31: Yearly maintenance
B32: FTE metric | C32: FTE (S/4 on-prem sigle metric) | D32: 790 | E32: =D32*E10 -> 0 | F32: =E32*0.17 -> 0
B33: HANA runtime (+15%) | E33: =E32*0.15 -> 0 | F33: =E33*0.17 -> 0
B34: Total | E34: =SUM(E32:E33) -> 0 | F34: =E34*0.17 -> 0
B36: Concur | C36: Metric | D36: Price per claim | E36: Total/year
B37: Claim | C37: No of claim/year | D37: 2.55 | E37: =D37*E11 -> 0
B39: DocuSign | C39: Metric | D39: Price per envelope | E39: Total/year
B40: Envelopes | C40: No of envelopes/year | D40: 6 | E40: =E12*D40 -> 0
B42: SAP IBP | C42: Metric | D42: Price per block | E42: Total/year
B43: Envelopes | C43: 500.000.000 EUR revenue / year | D43: 78158 | E43: =D43*E13 -> 0
B45: SAP TM | C45: Metric | D45: Price per block | E45: Total one time | F45: Yearly maintenance
C46: Freight spend year | D46: 20240 | E46: =E14*D46 -> 0 | F46: =E46*0.17 -> 0
B48: SAP EWM | C48: Metric | D48: Price per block | E48: Total one time | F48: Yearly maintenance
C49: Delivery items per day | D49: 58190 | E49: =E15*D49 -> 0 | F49: =E49*0.17 -> 0
